Workbook

Sheet crude clean
A2: Date | B2: ICE BRENT CRUDE M1 | C2: ICE BRENT CRUDE M2 | D2: ICE BRENT CRUDE M3 | E2: ICE BRENT CRUDE M4 | F2: ICE BRENT CRUDE M5 | G2: ICE BRENT CRUDE M6 | H2: ICE BRENT CRUDE M7 | I2: ICE BRENT CRUDE M8 | J2: ICE BRENT CRUDE M9 | K2: ICE BRENT CRUDE M10 | L2: ICE BRENT CRUDE M11 | M2: ICE BRENT CRUDE M12 | N2: NYMEX WTI CRUDE M1 | O2: NYMEX WTI CRUDE M2 | P2: NYMEX WTI CRUDE M3 | Q2: NYMEX WTI CRUDE M4 | R2: NYMEX WTI CRUDE M5 | S2: NYMEX WTI CRUDE M6 | T2: NYMEX WTI CRUDE M7 | U2: NYMEX WTI CRUDE M8 | V2: NYMEX WTI CRUDE M9 | W2: NYMEX WTI CRUDE M10 | X2: NYMEX WTI CRUDE M11 | Y2: NYMEX WTI CRUDE M12 | Z2: ICE DUBAI CRUDE M1 | AA2: ICE DUBAI CRUDE M2 | AB2: ICE DUBAI CRUDE M3 | AC2: ICE DUBAI CRUDE M4 | AD2: ICE DUBAI CRUDE M5 | AE2: ICE DUBAI CRUDE M6 | AF2: ICE DUBAI CRUDE M7 | AG2: ICE DUBAI CRUDE M8 | AH2: ICE DUBAI CRUDE M9 | AI2: ICE DUBAI CRUDE M10 | AJ2: ICE DUBAI CRUDE M11 | AK2: ICE DUBAI CRUDE M12
A3: ='raw data Crude oil'!A4 -> 42738 | B3: ='raw data Crude oil'!B4 -> 55.47 | C3: ='raw data Crude oil'!C4 -> 56.14 | D3: ='raw data Crude oil'!D4 -> 56.71 | E3: ='raw data Crude oil'!E4 -> 57.15 | F3: ='raw data Crude oil'!F4 -> 57.44 | G3: ='raw data Crude oil'!G4 -> 57.6 | H3: ='raw data Crude oil'!H4 -> 57.66 | ... AK3: ='raw data Crude oil'!AK4
A4: ='raw data Crude oil'!A5 -> 42739 | B4: ='raw data Crude oil'!B5 -> 56.46 | C4: ='raw data Crude oil'!C5 -> 57.09 | D4: ='raw data Crude oil'!D5 -> 57.63 | E4: ='raw data Crude oil'!E5 -> 58.07 | F4: ='raw data Crude oil'!F5 -> 58.36 | G4: ='raw data Crude oil'!G5 -> 58.51 | H4: ='raw data Crude oil'!H5 -> 58.57 | ... AK4: ='raw data Crude oil'!AK5 -> 0
A5: ='raw data Crude oil'!A6 -> 42740 | B5: ='raw data Crude oil'!B6 -> 56.89 | C5: ='raw data Crude oil'!C6 -> 57.48 | D5: ='raw data Crude oil'!D6 -> 57.98 | E5: ='raw data Crude oil'!E6 -> 58.39 | F5: ='raw data Crude oil'!F6 -> 58.66 | G5: ='raw data Crude oil'!G6 -> 58.81 | H5: ='raw data Crude oil'!H6 -> 58.86 | ... AK5: ='raw data Crude oil'!AK6 -> 0
A6: ='raw data Crude oil'!A7 -> 42741 | B6: ='raw data Crude oil'!B7 -> 57.1 | C6: ='raw data Crude oil'!C7 -> 57.68 | D6: ='raw data Crude oil'!D7 -> 58.17 | E6: ='raw data Crude oil'!E7 -> 58.57 | F6: ='raw data Crude oil'!F7 -> 58.84 | G6: ='raw data Crude oil'!G7 -> 58.98 | H6: ='raw data Crude oil'!H7 -> 59.03 | ... AK6: ='raw data Crude oil'!AK7 -> 0
A7: ='raw data Crude oil'!A8 -> 42744 | B7: ='raw data Crude oil'!B8 -> 54.94 | C7: ='raw data Crude oil'!C8 -> 55.56 | D7: ='raw data Crude oil'!D8 -> 56.09 | E7: ='raw data Crude oil'!E8 -> 56.53 | F7: ='raw data Crude oil'!F8 -> 56.83 | G7: ='raw data Crude oil'!G8 -> 57.01 | H7: ='raw data Crude oil'!H8 -> 57.08 | ... AK7: ='raw data Crude oil'!AK8 -> 0
A8: ='raw data Crude oil'!A9 -> 42745 | B8: ='raw data Crude oil'!B9 -> 53.64 | C8: ='raw data Crude oil'!C9 -> 54.26 | D8: ='raw data Crude oil'!D9 -> 54.79 | E8: ='raw data Crude oil'!E9 -> 55.25 | F8: ='raw data Crude oil'!F9 -> 55.58 | G8: ='raw data Crude oil'!G9 -> 55.79 | H8: ='raw data Crude oil'!H9 -> 55.89 | ... AK8: ='raw data Crude oil'!AK9 -> 0
A9: ='raw data Crude oil'!A10 -> 42746 | B9: ='raw data Crude oil'!B10 -> 55.1 | C9: ='raw data Crude oil'!C10 -> 55.6 | D9: ='raw data Crude oil'!D10 -> 56.09 | E9: ='raw data Crude oil'!E10 -> 56.51 | F9: ='raw data Crude oil'!F10 -> 56.78 | G9: ='raw data Crude oil'!G10 -> 56.94 | H9: ='raw data Crude oil'!H10 -> 57.02 | ... AK9: ='raw data Crude oil'!AK10 -> 0
A10: ='raw data Crude oil'!A11 -> 42747 | B10: ='raw data Crude oil'!B11 -> 56.01 | C10: ='raw data Crude oil'!C11 -> 56.49 | D10: ='raw data Crude oil'!D11 -> 56.98 | E10: ='raw data Crude oil'!E11 -> 57.42 | F10: ='raw data Crude oil'!F11 -> 57.7 | G10: ='raw data Crude oil'!G11 -> 57.85 | H10: ='raw data Crude oil'!H11 -> 57.9 | ... AK10: ='raw data Crude oil'!AK11 -> 0
A11: ='raw data Crude oil'!A12 -> 42748 | B11: ='raw data Crude oil'!B12 -> 55.45 | C11: ='raw data Crude oil'!C12 -> 55.91 | D11: ='raw data Crude oil'!D12 -> 56.38 | E11: ='raw data Crude oil'!E12 -> 56.8 | F11: ='raw data Crude oil'!F12 -> 57.08 | G11: ='raw data Crude oil'!G12 -> 57.23 | H11: ='raw data Crude oil'!H12 -> 57.28 | ... AK11: ='raw data Crude oil'!AK12 -> 0
A12: ='raw data Crude oil'!A13 -> 42751 | B12: ='raw data Crude oil'!B13 -> 55.86 | C12: ='raw data Crude oil'!C13 -> 56.28 | D12: ='raw data Crude oil'!D13 -> 56.73 | E12: ='raw data Crude oil'!E13 -> 57.14 | F12: ='raw data Crude oil'!F13 -> 57.42 | G12: ='raw data Crude oil'!G13 -> 57.57 | H12: ='raw data Crude oil'!H13 -> 57.63 | ... AK12: ='raw data Crude oil'!AK13 -> 0
A13: ='raw data Crude oil'!A14 -> 42752 | B13: ='raw data Crude oil'!B14 -> 55.47 | C13: ='raw data Crude oil'!C14 -> 55.94 | D13: ='raw data Crude oil'!D14 -> 56.44 | E13: ='raw data Crude oil'!E14 -> 56.89 | F13: ='raw data Crude oil'!F14 -> 57.19 | G13: ='raw data Crude oil'!G14 -> 57.37 | H13: ='raw data Crude oil'!H14 -> 57.45 | ... AK13: ='raw data Crude oil'!AK14 -> 0
A14: ='raw data Crude oil'!A15 -> 42753 | B14: ='raw data Crude oil'!B15 -> 53.92 | C14: ='raw data Crude oil'!C15 -> 54.41 | D14: ='raw data Crude oil'!D15 -> 54.93 | E14: ='raw data Crude oil'!E15 -> 55.4 | F14: ='raw data Crude oil'!F15 -> 55.73 | G14: ='raw data Crude oil'!G15 -> 55.93 | H14: ='raw data Crude oil'!H15 -> 56.03 | ... AK14: ='raw data Crude oil'!AK15 -> 0
... A3101: ='raw data Crude oil'!A3102 -> 0 | B3101: ='raw data Crude oil'!B3102 -> 0 | C3101: ='raw data Crude oil'!C3102 -> 0 | D3101: ='raw data Crude oil'!D3102 -> 0 | E3101: ='raw data Crude oil'!E3102 -> 0 | F3101: ='raw data Crude oil'!F3102 -> 0 | G3101: ='raw data Crude oil'!G3102 -> 0 | H3101: ='raw data Crude oil'!H3102 -> 0 | ... AK3101: ='raw data Crude oil'!AK3102 -> 0

Sheet raw data Crude oil
A2: =_xll.Storm.ExcelMacros.GvTableInfo("BlanksStrategy=UsePrevious;"&"IncludeAverage=False;"&"ShowSymbolNameInHeader=False;"&"SettleForClose=False;"&"FirstTime=False;"&"SelectedPeriod=Daily;"&"SelectedSpecType=DataRange;"&"DailyLastMode=TradedDays;"&"StartDate=01/01/2017 00:00:00;"&"EndDate;"&"StartDateRange;"&"EndDateRange;"&"NumOfPeriods=1300;"&"LastDate=03/20/2026 00:00:00;"&"UseLocalTime=False;"&"MovingAverageIntervals=;"&"NumberOfResultLeafs=36;"&"NumberOfFields=36;"&"NumberOfPeriods=2379;"&"Version=4.21.1.0;"&"WorkbookVersion=5;"&"ExpirationDate=04/03/2026 00:00:00;"&"SymbolSelectorWidth=1144;"&"FieldSelectorWidth=350.4;", 639095931137609000) -> * | B2: =_xll.Storm.ExcelMacros.GvDescription("/BRN<0>", B3, "daily", "2", "0", "", "", , "p", , , , , , "Hundredths", , FALSE, ) -> ICE Brent Crude Oil Futures (Front Month) | C2: =_xll.Storm.ExcelMacros.GvDescription("/BRN<1>", C3, "daily", "2", "1", "", "", , "p", , , , , , "Hundredths", , FALSE, ) -> ICE Brent Crude Oil Futures (2nd Month) | D2: =_xll.Storm.ExcelMacros.GvDescription("/BRN<2>", D3, "daily", "2", "2", "", "", , "p", , , , , , "Hundredths", , FALSE, ) -> ICE Brent Crude Oil Futures (3rd Month) | E2: =_xll.Storm.ExcelMacros.GvDescription("/BRN<3>", E3, "daily", "2", "3", "", "", , "p", , , , , , "Hundredths", , FALSE, ) -> ICE Brent Crude Oil Futures (4th Month) | F2: =_xll.Storm.ExcelMacros.GvDescription("/BRN<4>", F3, "daily", "2", "4", "", "", , "p", , , , , , "Hundredths", , FALSE, ) -> ICE Brent Crude Oil Futures (5th Month) | G2: =_xll.Storm.ExcelMacros.GvDescription("/BRN<5>", G3, "daily", "2", "5", "", "", , "p", , , , , , "Hundredths", , FALSE, ) -> ICE Brent Crude Oil Futures (6th Month) | H2: =_xll.Storm.ExcelMacros.GvDescription("/BRN<6>", H3, "daily", "2", "6", "", "", , "p", , , , , , "Hundredths", , FALSE, ) -> ICE Brent Crude Oil Futures (7th Month) | I2: =_xll.Storm.ExcelMacros.GvDescription("/BRN<7>", I3, "daily", "2", "7", "", "", , "p", , , , , , "Hundredths", , FALSE, ) -> ICE Brent Crude Oil Futures (8th Month) | J2: =_xll.Storm.ExcelMacros.GvDescription("/BRN<8>", J3, "daily", "2", "8", "", "", , "p", , , , , , "Hundredths", , FALSE, ) -> ICE Brent Crude Oil Futures (9th Month) | K2: =_xll.Storm.ExcelMacros.GvDescription("/BRN<9>", K3, "daily", "2", "9", "", "", , "p", , , , , , "Hundredths", , FALSE, ) -> ICE Brent Crude Oil Futures (10th Month) | L2: =_xll.Storm.ExcelMacros.GvDescription("/BRN<10>", L3, "daily", "2", "10", "", "", , "p", , , , , , "Hundredths", , FALSE, ) -> ICE Brent Crude Oil Futures (11th Month) | M2: =_xll.Storm.ExcelMacros.GvDescription("/BRN<11>", M3, "daily", "2", "11", "", "", , "p", , , , , , "Hundredths", , FALSE, ) -> ICE Brent Crude Oil Futures (12th Month) | N2: =_xll.Storm.ExcelMacros.GvDescription("/GCL<0>", N3, "daily", "2", "12", "", "", , "p", , , , , , "Hundredths", , FALSE, ) -> NYMEX Light Sweet Crude Oil (WTI) Futures Electronic (Front Month) | O2: =_xll.Storm.ExcelMacros.GvDescription("/GCL<1>", O3, "daily", "2", "13", "", "", , "p", , , , , , "Hundredths", , FALSE, ) -> NYMEX Light Sweet Crude Oil (WTI) Futures Electronic (2nd Month) | P2: =_xll.Storm.ExcelMacros.GvDescription("/GCL<2>", P3, "daily", "2", "14", "", "", , "p", , , , , , "Hundredths", , FALSE, ) -> NYMEX Light Sweet Crude Oil (WTI) Futures Electronic (3rd Month) | Q2: =_xll.Storm.ExcelMacros.GvDescription("/GCL<3>", Q3, "daily", "2", "15", "", "", , "p", , , , , , "Hundredths", , FALSE, ) -> NYMEX Light Sweet Crude Oil (WTI) Futures Electronic (4th Month) | R2: =_xll.Storm.ExcelMacros.GvDescription("/GCL<4>", R3, "daily", "2", "16", "", "", , "p", , , , , , "Hundredths", , FALSE, ) -> NYMEX Light Sweet Crude Oil (WTI) Futures Electronic (5th Month) | S2: =_xll.Storm.ExcelMacros.GvDescription("/GCL<5>", S3, "daily", "2", "17", "", "", , "p", , , , , , "Hundredths", , FALSE, ) -> NYMEX Light Sweet Crude Oil (WTI) Futures Electronic (6th Month) | T2: =_xll.Storm.ExcelMacros.GvDescription("/GCL<6>", T3, "daily", "2", "18", "", "", , "p", , , , , , "Hundredths", , FALSE, ) -> NYMEX Light Sweet Crude Oil (WTI) Futures Electronic (7th Month) | U2: =_xll.Storm.ExcelMacros.GvDescription("/GCL<7>", U3, "daily", "2", "19", "", "", , "p", , , , , , "Hundredths", , FALSE, ) -> NYMEX Light Sweet Crude Oil (WTI) Futures Electronic (8th Month) | V2: =_xll.Storm.ExcelMacros.GvDescription("/GCL<8>", V3, "daily", "2", "20", "", "", , "p", , , , , , "Hundredths", , FALSE, ) -> NYMEX Light Sweet Crude Oil (WTI) Futures Electronic (9th Month) | W2: =_xll.Storm.ExcelMacros.GvDescription("/GCL<9>", W3, "daily", "2", "21", "", "", , "p", , , , , , "Hundredths", , FALSE, ) -> NYMEX Light Sweet Crude Oil (WTI) Futures Electronic (10th Month) | X2: =_xll.Storm.ExcelMacros.GvDescription("/GCL<10>", X3, "daily", "2", "22", "", "", , "p", , , , , , "Hundredths", , FALSE, ) -> NYMEX Light Sweet Crude Oil (WTI) Futures Electronic (11th Month) | Y2: =_xll.Storm.ExcelMacros.GvDescription("/GCL<11>", Y3, "daily", "2", "23", "", "", , "p", , , , , , "Hundredths", , FALSE, ) -> NYMEX Light Sweet Crude Oil (WTI) Futures Electronic (12th Month) | Z2: =_xll.Storm.ExcelMacros.GvDescription("/DBI<0>", Z3, "daily", "2", "24", "", "", , "p", , , , , , "Thousandths", , FALSE, ) -> ICE Dubai 1st Line Futures (Front Month) | AA2: =_xll.Storm.ExcelMacros.GvDescription("/DBI<1>", AA3, "daily", "2", "25", "", "", , "p", , , , , , "Thousandths", , FALSE, ) -> ICE Dubai 1st Line Futures (2nd Month) | AB2: =_xll.Storm.ExcelMacros.GvDescription("/DBI<2>", AB3, "daily", "2", "26", "", "", , "p", , , , , , "Thousandths", , FALSE, ) -> ICE Dubai 1st Line Futures (3rd Month) | AC2: =_xll.Storm.ExcelMacros.GvDescription("/DBI<3>", AC3, "daily", "2", "27", "", "", , "p", , , , , , "Thousandths", , FALSE, ) -> ICE Dubai 1st Line Futures (4th Month) | AD2: =_xll.Storm.ExcelMacros.GvDescription("/DBI<4>", AD3, "daily", "2", "28", "", "", , "p", , , , , , "Thousandths", , FALSE, ) -> ICE Dubai 1st Line Futures (5th Month) | AE2: =_xll.Storm.ExcelMacros.GvDescription("/DBI<5>", AE3, "daily", "2", "29", "", "", , "p", , , , , , "Thousandths", , FALSE, ) -> ICE Dubai 1st Line Futures (6th Month) | AF2: =_xll.Storm.ExcelMacros.GvDescription("/DBI<6>", AF3, "daily", "2", "30", "", "", , "p", , , , , , "Thousandths", , FALSE, ) -> ICE Dubai 1st Line Futures (7th Month) | AG2: =_xll.Storm.ExcelMacros.GvDescription("/DBI<7>", AG3, "daily", "2", "31", "", "", , "p", , , , , , "Thousandths", , FALSE, ) -> ICE Dubai 1st Line Futures (8th Month) | AH2: =_xll.Storm.ExcelMacros.GvDescription("/DBI<8>", AH3, "daily", "2", "32", "", "", , "p", , , , , , "Thousandths", , FALSE, ) -> ICE Dubai 1st Line Futures (9th Month) | AI2: =_xll.Storm.ExcelMacros.GvDescription("/DBI<9>", AI3, "daily", "2", "33", "", "", , "p", , , , , , "Thousandths", , FALSE, ) -> ICE Dubai 1st Line Futures (10th Month) | AJ2: =_xll.Storm.ExcelMacros.GvDescription("/DBI<10>", AJ3, "daily", "2", "34", "", "", , "p", , , , , , "Thousandths", , FALSE, ) -> ICE Dubai 1st Line Futures (11th Month) | AK2: =_xll.Storm.ExcelMacros.GvDescription("/DBI<11>", AK3, "daily", "2", "35", "", "", , "p", , , , , , "Thousandths", , FALSE, ) -> ICE Dubai 1st Line Futures (12th Month)
A3: Date | B3: Close | C3: Close | D3: Close | E3: Close | F3: Close | G3: Close | H3: Close | I3: Close | J3: Close | K3: Close | L3: Close | M3: Close | N3: Close | O3: Close | P3: Close | Q3: Close | R3: Close | S3: Close | T3: Close | U3: Close | V3: Close | W3: Close | X3: Close | Y3: Close | Z3: Close | AA3: Close | AB3: Close | AC3: Close | AD3: Close | AE3: Close | AF3: Close | AG3: Close | AH3: Close | AI3: Close | AJ3: Close | AK3: Close
A4: =DATE(2017, 1, 3) -> 42738 | B4: =IF(ISERROR(_xll.Storm.ExcelMacros.GvDaily("/BRN<0>", B$3, A4, "", "", "", , "p", , , , , , "Hundredths", , FALSE, , "")), 55.47, _xll.Storm.ExcelMacros.GvDaily("/BRN<0>", B$3, A4, "", "", "", , "p", , , , , , "Hundredths", , FALSE, , "")) -> 55.47 | C4: =IF(ISERROR(_xll.Storm.ExcelMacros.GvDaily("/BRN<1>", C$3, A4, "", "", "", , "p", , , , , , "Hundredths", , FALSE, , "")), 56.14, _xll.Storm.ExcelMacros.GvDaily("/BRN<1>", C$3, A4, "", "", "", , "p", , , , , , "Hundredths", , FALSE, , "")) -> 56.14 | D4: =IF(ISERROR(_xll.Storm.ExcelMacros.GvDaily("/BRN<2>", D$3, A4, "", "", "", , "p", , , , , , "Hundredths", , FALSE, , "")), 56.71, _xll.Storm.ExcelMacros.GvDaily("/BRN<2>", D$3, A4, "", "", "", , "p", , , , , , "Hundredths", , FALSE, , "")) -> 56.71 | E4: =IF(ISERROR(_xll.Storm.ExcelMacros.GvDaily("/BRN<3>", E$3, A4, "", "", "", , "p", , , , , , "Hundredths", , FALSE, , "")), 57.15, _xll.Storm.ExcelMacros.GvDaily("/BRN<3>", E$3, A4, "", "", "", , "p", , , , , , "Hundredths", , FALSE, , "")) -> 57.15 | F4: =IF(ISERROR(_xll.Storm.ExcelMacros.GvDaily("/BRN<4>", F$3, A4, "", "", "", , "p", , , , , , "Hundredths", , FALSE, , "")), 57.44, _xll.Storm.ExcelMacros.GvDaily("/BRN<4>", F$3, A4, "", "", "", , "p", , , , , , "Hundredths", , FALSE, , "")) -> 57.44 | G4: =IF(ISERROR(_xll.Storm.ExcelMacros.GvDaily("/BRN<5>", G$3, A4, "", "", "", , "p", , , , , , "Hundredths", , FALSE, , "")), 57.6, _xll.Storm.ExcelMacros.GvDaily("/BRN<5>", G$3, A4, "", "", "", , "p", , , , , , "Hundredths", , FALSE, , "")) -> 57.6 | H4: =IF(ISERROR(_xll.Storm.ExcelMacros.GvDaily("/BRN<6>", H$3, A4, "", "", "", , "p", , , , , , "Hundredths", , FALSE, , "")), 57.66, _xll.Storm.ExcelMacros.GvDaily("/BRN<6>", H$3, A4, "", "", "", , "p", , , , , , "Hundredths", , FALSE, , "")) -> 57.66 | I4: =IF(ISERROR(_xll.Storm.ExcelMacros.GvDaily("/BRN<7>", I$3, A4, "", "", "", , "p", , , , , , "Hundredths", , FALSE, , "")), 57.66, _xll.Storm.ExcelMacros.GvDaily("/BRN<7>", I$3, A4, "", "", "", , "p", , , , , , "Hundredths", , FALSE, , "")) -> 57.66 | J4: =IF(ISERROR(_xll.Storm.ExcelMacros.GvDaily("/BRN<8>", J$3, A4, "", "", "", , "p", , , , , , "Hundredths", , FALSE, , "")), 57.64, _xll.Storm.ExcelMacros.GvDaily("/BRN<8>", J$3, A4, "", "", "", , "p", , , , , , "Hundredths", , FALSE, , "")) -> 57.64 | K4: =IF(ISERROR(_xll.Storm.ExcelMacros.GvDaily("/BRN<9>", K$3, A4, "", "", "", , "p", , , , , , "Hundredths", , FALSE, , "")), 57.6, _xll.Storm.ExcelMacros.GvDaily("/BRN<9>", K$3, A4, "", "", "", , "p", , , , , , "Hundredths", , FALSE, , "")) -> 57.6 | L4: =IF(ISERROR(_xll.Storm.ExcelMacros.GvDaily("/BRN<10>", L$3, A4, "", "", "", , "p", , , , , , "Hundredths", , FALSE, , "")), 57.56, _xll.Storm.ExcelMacros.GvDaily("/BRN<10>", L$3, A4, "", "", "", , "p", , , , , , "Hundredths", , FALSE, , "")) -> 57.56 | M4: =IF(ISERROR(_xll.Storm.ExcelMacros.GvDaily("/BRN<11>", M$3, A4, "", "", "", , "p", , , , , , "Hundredths", , FALSE, , "")), 57.52, _xll.Storm.ExcelMacros.GvDaily("/BRN<11>", M$3, A4, "", "", "", , "p", , , , , , "Hundredths", , FALSE, , "")) -> 57.52 | N4: =IF(ISERROR(_xll.Storm.ExcelMacros.GvDaily("/GCL<0>", N$3, A4, "", "", "", , "p", , , , , , "Hundredths", , FALSE, , "")), 52.33, _xll.Storm.ExcelMacros.GvDaily("/GCL<0>", N$3, A4, "", "", "", , "p", , , , , , "Hundredths", , FALSE, , "")) -> 52.33 | O4: =IF(ISERROR(_xll.Storm.ExcelMacros.GvDaily("/GCL<1>", O$3, A4, "", "", "", , "p", , , , , , "Hundredths", , FALSE, , "")), 53.29, _xll.Storm.ExcelMacros.GvDaily("/GCL<1>", O$3, A4, "", "", "", , "p", , , , , , "Hundredths", , FALSE, , "")) -> 53.29 | P4: =IF(ISERROR(_xll.Storm.ExcelMacros.GvDaily("/GCL<2>", P$3, A4, "", "", "", , "p", , , , , , "Hundredths", , FALSE, , "")), 54.12, _xll.Storm.ExcelMacros.GvDaily("/GCL<2>", P$3, A4, "", "", "", , "p", , , , , , "Hundredths", , FALSE, , "")) -> 54.12 | Q4: =IF(ISERROR(_xll.Storm.ExcelMacros.GvDaily("/GCL<3>", Q$3, A4, "", "", "", , "p", , , , , , "Hundredths", , FALSE, , "")), 54.81, _xll.Storm.ExcelMacros.GvDaily("/GCL<3>", Q$3, A4, "", "", "", , "p", , , , , , "Hundredths", , FALSE, , "")) -> 54.81 | R4: =IF(ISERROR(_xll.Storm.ExcelMacros.GvDaily("/GCL<4>", R$3, A4, "", "", "", , "p", , , , , , "Hundredths", , FALSE, , "")), 55.32, _xll.Storm.ExcelMacros.GvDaily("/GCL<4>", R$3, A4, "", "", "", , "p", , , , , , "Hundredths", , FALSE, , "")) -> 55.32 | S4: =IF(ISERROR(_xll.Storm.ExcelMacros.GvDaily("/GCL<5>", S$3, A4, "", "", "", , "p", , , , , , "Hundredths", , FALSE, , "")), 55.65, _xll.Storm.ExcelMacros.GvDaily("/GCL<5>", S$3, A4, "", "", "", , "p", , , , , , "Hundredths", , FALSE, , "")) -> 55.65 | T4: =IF(ISERROR(_xll.Storm.ExcelMacros.GvDaily("/GCL<6>", T$3, A4, "", "", "", , "p", , , , , , "Hundredths", , FALSE, , "")), 55.84, _xll.Storm.ExcelMacros.GvDaily("/GCL<6>", T$3, A4, "", "", "", , "p", , , , , , "Hundredths", , FALSE, , "")) -> 55.84 | U4: =IF(ISERROR(_xll.Storm.ExcelMacros.GvDaily("/GCL<7>", U$3, A4, "", "", "", , "p", , , , , , "Hundredths", , FALSE, , "")), 55.95, _xll.Storm.ExcelMacros.GvDaily("/GCL<7>", U$3, A4, "", "", "", , "p", , , , , , "Hundredths", , FALSE, , "")) -> 55.95 | V4: =IF(ISERROR(_xll.Storm.ExcelMacros.GvDaily("/GCL<8>", V$3, A4, "", "", "", , "p", , , , , , "Hundredths", , FALSE, , "")), 56.01, _xll.Storm.ExcelMacros.GvDaily("/GCL<8>", V$3, A4, "", "", "", , "p", , , , , , "Hundredths", , FALSE, , "")) -> 56.01 | W4: =IF(ISERROR(_xll.Storm.ExcelMacros.GvDaily("/GCL<9>", W$3, A4, "", "", "", , "p", , , , , , "Hundredths", , FALSE, , "")), 56.04, _xll.Storm.ExcelMacros.GvDaily("/GCL<9>", W$3, A4, "", "", "", , "p", , , , , , "Hundredths", , FALSE, , "")) -> 56.04 | X4: =IF(ISERROR(_xll.Storm.ExcelMacros.GvDaily("/GCL<10>", X$3, A4, "", "", "", , "p", , , , , , "Hundredths", , FALSE, , "")), 56.06, _xll.Storm.ExcelMacros.GvDaily("/GCL<10>", X$3, A4, "", "", "", , "p", , , , , , "Hundredths", , FALSE, , "")) -> 56.06 | Y4: =IF(ISERROR(_xll.Storm.ExcelMacros.GvDaily("/GCL<11>", Y$3, A4, "", "", "", , "p", , , , , , "Hundredths", , FALSE, , "")), 56, _xll.Storm.ExcelMacros.GvDaily("/GCL<11>", Y$3, A4, "", "", "", , "p", , , , , , "Hundredths", , FALSE, , "")) -> 56 | Z4: =IF(ISERROR(_xll.Storm.ExcelMacros.GvDaily("/DBI<0>", Z$3, A4, "", "", "", , "p", , , , , , "Thousandths", , FALSE, , "")), , _xll.Storm.ExcelMacros.GvDaily("/DBI<0>", Z$3, A4, "", "", "", , "p", , , , , , "Thousandths", , FALSE, , "")) | AA4: =IF(ISERROR(_xll.Storm.ExcelMacros.GvDaily("/DBI<1>", AA$3, A4, "", "", "", , "p", , , , , , "Thousandths", , FALSE, , "")), , _xll.Storm.ExcelMacros.GvDaily("/DBI<1>", AA$3, A4, "", "", "", , "p", , , , , , "Thousandths", , FALSE, , "")) | AB4: =IF(ISERROR(_xll.Storm.ExcelMacros.GvDaily("/DBI<2>", AB$3, A4, "", "", "", , "p", , , , , , "Thousandths", , FALSE, , "")), , _xll.Storm.ExcelMacros.GvDaily("/DBI<2>", AB$3, A4, "", "", "", , "p", , , , , , "Thousandths", , FALSE, , "")) | AC4: =IF(ISERROR(_xll.Storm.ExcelMacros.GvDaily("/DBI<3>", AC$3, A4, "", "", "", , "p", , , , , , "Thousandths", , FALSE, , "")), , _xll.Storm.ExcelMacros.GvDaily("/DBI<3>", AC$3, A4, "", "", "", , "p", , , , , , "Thousandths", , FALSE, , "")) | AD4: =IF(ISERROR(_xll.Storm.ExcelMacros.GvDaily("/DBI<4>", AD$3, A4, "", "", "", , "p", , , , , , "Thousandths", , FALSE, , "")), , _xll.Storm.ExcelMacros.GvDaily("/DBI<4>", AD$3, A4, "", "", "", , "p", , , , , , "Thousandths", , FALSE, , "")) | AE4: =IF(ISERROR(_xll.Storm.ExcelMacros.GvDaily("/DBI<5>", AE$3, A4, "", "", "", , "p", , , , , , "Thousandths", , FALSE, , "")), , _xll.Storm.ExcelMacros.GvDaily("/DBI<5>", AE$3, A4, "", "", "", , "p", , , , , , "Thousandths", , FALSE, , "")) | AF4: =IF(ISERROR(_xll.Storm.ExcelMacros.GvDaily("/DBI<6>", AF$3, A4, "", "", "", , "p", , , , , , "Thousandths", , FALSE, , "")), , _xll.Storm.ExcelMacros.GvDaily("/DBI<6>", AF$3, A4, "", "", "", , "p", , , , , , "Thousandths", , FALSE, , "")) | AG4: =IF(ISERROR(_xll.Storm.ExcelMacros.GvDaily("/DBI<7>", AG$3, A4, "", "", "", , "p", , , , , , "Thousandths", , FALSE, , "")), , _xll.Storm.ExcelMacros.GvDaily("/DBI<7>", AG$3, A4, "", "", "", , "p", , , , , , "Thousandths", , FALSE, , "")) | AH4: =IF(ISERROR(_xll.Storm.ExcelMacros.GvDaily("/DBI<8>", AH$3, A4, "", "", "", , "p", , , , , , "Thousandths", , FALSE, , "")), , _xll.Storm.ExcelMacros.GvDaily("/DBI<8>", AH$3, A4, "", "", "", , "p", , , , , , "Thousandths", , FALSE, , "")) | AI4: =IF(ISERROR(_xll.Storm.ExcelMacros.GvDaily("/DBI<9>", AI$3, A4, "", "", "", , "p", , , , , , "Thousandths", , FALSE, , "")), , _xll.Storm.ExcelMacros.GvDaily("/DBI<9>", AI$3, A4, "", "", "", , "p", , , , , , "Thousandths", , FALSE, , "")) | AJ4: =IF(ISERROR(_xll.Storm.ExcelMacros.GvDaily("/DBI<10>", AJ$3, A4, "", "", "", , "p", , , , , , "Thousandths", , FALSE, , "")), , _xll.Storm.ExcelMacros.GvDaily("/DBI<10>", AJ$3, A4, "", "", "", , "p", , , , , , "Thousandths", , FALSE, , "")) | AK4: =IF(ISERROR(_xll.Storm.ExcelMacros.GvDaily("/DBI<11>", AK$3, A4, "", "", "", , "p", , , , , , "Thousandths", , FALSE, , "")), , _xll.Storm.ExcelMacros.GvDaily("/DBI<11>", AK$3, A4, "", "", "", , "p", , , , , , "Thousandths", , FALSE, , ""))
A5: =DATE(2017, 1, 4) -> 42739 | B5: 56.46 | C5: 57.09 | D5: 57.63 | E5: 58.07 | F5: 58.36 | G5: 58.51 | H5: 58.57 | I5: 58.56 | J5: 58.53 | K5: 58.49 | L5: 58.44 | M5: 58.4 | N5: 53.26 | O5: 54.22 | P5: 55.05 | Q5: 55.75 | R5: 56.29 | S5: 56.63 | T5: 56.82 | U5: 56.94 | V5: 57 | W5: 57.03 | X5: 57.06 | Y5: 57.01
A6: =DATE(2017, 1, 5) -> 42740 | B6: 56.89 | C6: 57.48 | D6: 57.98 | E6: 58.39 | F6: 58.66 | G6: 58.81 | H6: 58.86 | I6: 58.85 | J6: 58.82 | K6: 58.77 | L6: 58.71 | M6: 58.67 | N6: 53.76 | O6: 54.68 | P6: 55.49 | Q6: 56.17 | R6: 56.68 | S6: 57.01 | T6: 57.19 | U6: 57.3 | V6: 57.35 | W6: 57.39 | X6: 57.43 | Y6: 57.39
A7: =DATE(2017, 1, 6) -> 42741 | B7: 57.1 | C7: 57.68 | D7: 58.17 | E7: 58.57 | F7: 58.84 | G7: 58.98 | H7: 59.03 | I7: 59.02 | J7: 59 | K7: 58.94 | L7: 58.89 | M7: 58.84 | N7: 53.99 | O7: 54.87 | P7: 55.68 | Q7: 56.37 | R7: 56.88 | S7: 57.21 | T7: 57.4 | U7: 57.51 | V7: 57.57 | W7: 57.62 | X7: 57.66 | Y7: 57.63
A8: =DATE(2017, 1, 9) -> 42744 | B8: 54.94 | C8: 55.56 | D8: 56.09 | E8: 56.53 | F8: 56.83 | G8: 57.01 | H8: 57.08 | I8: 57.1 | J8: 57.09 | K8: 57.07 | L8: 57.04 | M8: 57.01 | N8: 51.96 | O8: 52.87 | P8: 53.72 | Q8: 54.47 | R8: 55.05 | S8: 55.43 | T8: 55.67 | U8: 55.83 | V8: 55.94 | W8: 56.02 | X8: 56.09 | Y8: 56.09
A9: =DATE(2017, 1, 10) -> 42745 | B9: 53.64 | C9: 54.26 | D9: 54.79 | E9: 55.25 | F9: 55.58 | G9: 55.79 | H9: 55.89 | I9: 55.94 | J9: 55.96 | K9: 55.95 | L9: 55.94 | M9: 55.92 | N9: 50.82 | O9: 51.7 | P9: 52.53 | Q9: 53.28 | R9: 53.87 | S9: 54.27 | T9: 54.53 | U9: 54.72 | V9: 54.87 | W9: 54.99 | X9: 55.1 | Y9: 55.15
A10: =DATE(2017, 1, 11) -> 42746 | B10: 55.1 | C10: 55.6 | D10: 56.09 | E10: 56.51 | F10: 56.78 | G10: 56.94 | H10: 57.02 | I10: 57.05 | J10: 57.06 | K10: 57.04 | L10: 57.02 | M10: 56.99 | N10: 52.25 | O10: 53.06 | P10: 53.87 | Q10: 54.59 | R10: 55.17 | S10: 55.56 | T10: 55.81 | U10: 55.99 | V10: 56.12 | W10: 56.21 | X10: 56.29 | Y10: 56.31
A11: =DATE(2017, 1, 12) -> 42747 | B11: 56.01 | C11: 56.49 | D11: 56.98 | E11: 57.42 | F11: 57.7 | G11: 57.85 | H11: 57.9 | I11: 57.92 | J11: 57.92 | K11: 57.89 | L11: 57.86 | M11: 57.82 | N11: 53.01 | O11: 53.84 | P11: 54.65 | Q11: 55.39 | R11: 55.99 | S11: 56.4 | T11: 56.64 | U11: 56.81 | V11: 56.92 | W11: 56.99 | X11: 57.05 | Y11: 57.05
A12: =DATE(2017, 1, 13) -> 42748 | B12: 55.45 | C12: 55.91 | D12: 56.38 | E12: 56.8 | F12: 57.08 | G12: 57.23 | H12: 57.28 | I12: 57.3 | J12: 57.3 | K12: 57.26 | L12: 57.23 | M12: 57.18 | N12: 52.37 | O12: 53.15 | P12: 53.95 | Q12: 54.68 | R12: 55.27 | S12: 55.67 | T12: 55.91 | U12: 56.08 | V12: 56.2 | W12: 56.29 | X12: 56.36 | Y12: 56.37
A13: =DATE(2017, 1, 16) -> 42751 | B13: 55.86 | C13: 56.28 | D13: 56.73 | E13: 57.14 | F13: 57.42 | G13: 57.57 | H13: 57.63 | I13: 57.64 | J13: 57.63 | K13: 57.6 | L13: 57.57 | M13: 57.52 | N13: 52.37 | O13: 53.15 | P13: 53.95 | Q13: 54.68 | R13: 55.27 | S13: 55.67 | T13: 55.91 | U13: 56.08 | V13: 56.2 | W13: 56.29 | X13: 56.36 | Y13: 56.37
A14: =DATE(2017, 1, 17) -> 42752 | B14: 55.47 | C14: 55.94 | D14: 56.44 | E14: 56.89 | F14: 57.19 | G14: 57.37 | H14: 57.45 | I14: 57.48 | J14: 57.49 | K14: 57.48 | L14: 57.46 | M14: 57.42 | N14: 52.48 | O14: 53.26 | P14: 54.03 | Q14: 54.75 | R14: 55.33 | S14: 55.73 | T14: 55.96 | U14: 56.1 | V14: 56.18 | W14: 56.23 | X14: 56.27 | Y14: 56.25
A15: =DATE(2017, 1, 18) -> 42753 | B15: 53.92 | C15: 54.41 | D15: 54.93 | E15: 55.4 | F15: 55.73 | G15: 55.93 | H15: 56.03 | I15: 56.08 | J15: 56.1 | K15: 56.11 | L15: 56.11 | M15: 56.1 | N15: 51.08 | O15: 51.89 | P15: 52.66 | Q15: 53.37 | R15: 53.95 | S15: 54.35 | T15: 54.59 | U15: 54.74 | V15: 54.83 | W15: 54.89 | X15: 54.95 | Y15: 54.96
A16: =DATE(2017, 1, 19) -> 42754 | B16: 54.16 | C16: 54.69 | D16: 55.21 | E16: 55.67 | F16: 55.99 | G16: 56.19 | H16: 56.29 | I16: 56.34 | J16: 56.36 | K16: 56.37 | L16: 56.37 | M16: 56.36 | N16: 51.37 | O16: 52.12 | P16: 52.84 | Q16: 53.5 | R16: 54.05 | S16: 54.45 | T16: 54.69 | U16: 54.85 | V16: 54.95 | W16: 55.02 | X16: 55.08 | Y16: 55.09
A17: =DATE(2017, 1, 20) -> 42755 | B17: 55.49 | C17: 55.98 | D17: 56.5 | E17: 56.94 | F17: 57.25 | G17: 57.44 | H17: 57.53 | I17: 57.56 | J17: 57.57 | K17: 57.57 | L17: 57.55 | M17: 57.54 | N17: 52.42 | O17: 53.22 | P17: 53.96 | Q17: 54.62 | R17: 55.16 | S17: 55.54 | T17: 55.75 | U17: 55.89 | V17: 55.97 | W17: 56.04 | X17: 56.1 | Y17: 56.1
A18: =DATE(2017, 1, 23) -> 42758 | B18: 55.23 | C18: 55.63 | D18: 56.11 | E18: 56.54 | F18: 56.84 | G18: 57.02 | H18: 57.11 | I18: 57.12 | J18: 57.12 | K18: 57.11 | L18: 57.09 | M18: 57.06 | N18: 52.75 | O18: 53.5 | P18: 54.17 | Q18: 54.71 | R18: 55.1 | S18: 55.33 | T18: 55.48 | U18: 55.58 | V18: 55.66 | W18: 55.73 | X18: 55.75 | Y18: 55.76
A19: =DATE(2017, 1, 24) -> 42759 | B19: 55.44 | C19: 55.85 | D19: 56.32 | E19: 56.74 | F19: 57.03 | G19: 57.21 | H19: 57.29 | I19: 57.29 | J19: 57.28 | K19: 57.26 | L19: 57.23 | M19: 57.19 | N19: 53.18 | O19: 53.86 | P19: 54.46 | Q19: 54.96 | R19: 55.33 | S19: 55.54 | T19: 55.67 | U19: 55.76 | V19: 55.82 | W19: 55.88 | X19: 55.89 | Y19: 55.9
A20: =DATE(2017, 1, 25) -> 42760 | B20: 55.08 | C20: 55.42 | D20: 55.83 | E20: 56.22 | F20: 56.49 | G20: 56.67 | H20: 56.74 | I20: 56.74 | J20: 56.72 | K20: 56.7 | L20: 56.67 | M20: 56.63 | N20: 52.75 | O20: 53.39 | P20: 53.95 | Q20: 54.43 | R20: 54.79 | S20: 55.02 | T20: 55.17 | U20: 55.27 | V20: 55.35 | W20: 55.42 | X20: 55.45 | Y20: 55.47
A21: =DATE(2017, 1, 26) -> 42761 | B21: 56.24 | C21: 56.49 | D21: 56.87 | E21: 57.21 | F21: 57.43 | G21: 57.55 | H21: 57.58 | I21: 57.55 | J21: 57.51 | K21: 57.47 | L21: 57.41 | M21: 57.36 | N21: 53.78 | O21: 54.38 | P21: 54.9 | Q21: 55.34 | R21: 55.65 | S21: 55.85 | T21: 56 | U21: 56.09 | V21: 56.16 | W21: 56.22 | X21: 56.24 | Y21: 56.26
A22: =DATE(2017, 1, 27) -> 42762 | B22: 55.52 | C22: 55.7 | D22: 56.05 | E22: 56.36 | F22: 56.55 | G22: 56.64 | H22: 56.65 | I22: 56.61 | J22: 56.57 | K22: 56.53 | L22: 56.47 | M22: 56.41 | N22: 53.17 | O22: 53.75 | P22: 54.25 | Q22: 54.67 | R22: 54.97 | S22: 55.15 | T22: 55.28 | U22: 55.36 | V22: 55.43 | W22: 55.49 | X22: 55.53 | Y22: 55.56
A23: =DATE(2017, 1, 30) -> 42765 | B23: 55.23 | C23: 55.32 | D23: 55.69 | E23: 56.02 | F23: 56.25 | G23: 56.38 | H23: 56.41 | I23: 56.39 | J23: 56.35 | K23: 56.32 | L23: 56.27 | M23: 56.22 | N23: 52.63 | O23: 53.24 | P23: 53.78 | Q23: 54.24 | R23: 54.57 | S23: 54.78 | T23: 54.93 | U23: 55.04 | V23: 55.13 | W23: 55.21 | X23: 55.27 | Y23: 55.32
A24: =DATE(2017, 1, 31) -> 42766 | B24: 55.7 | C24: 55.58 | D24: 55.91 | E24: 56.21 | F24: 56.42 | G24: 56.54 | H24: 56.58 | I24: 56.57 | J24: 56.54 | K24: 56.51 | L24: 56.48 | M24: 56.43 | N24: 52.81 | O24: 53.42 | P24: 53.94 | Q24: 54.38 | R24: 54.7 | S24: 54.9 | T24: 55.05 | U24: 55.16 | V24: 55.25 | W24: 55.33 | X24: 55.38 | Y24: 55.42
A25: =DATE(2017, 2, 1) -> 42767 | B25: 56.8 | C25: 57.12 | D25: 57.4 | E25: 57.59 | F25: 57.69 | G25: 57.72 | H25: 57.69 | I25: 57.65 | J25: 57.61 | K25: 57.57 | L25: 57.52 | M25: 57.47 | N25: 53.88 | O25: 54.49 | P25: 54.99 | Q25: 55.41 | R25: 55.69 | S25: 55.85 | T25: 55.95 | U25: 56.02 | V25: 56.09 | W25: 56.15 | X25: 56.18 | Y25: 56.2
A26: =DATE(2017, 2, 2) -> 42768 | B26: 56.56 | C26: 56.85 | D26: 57.11 | E26: 57.28 | F26: 57.37 | G26: 57.4 | H26: 57.38 | I26: 57.34 | J26: 57.31 | K26: 57.26 | L26: 57.2 | M26: 57.14 | N26: 53.54 | O26: 54.17 | P26: 54.67 | Q26: 55.09 | R26: 55.39 | S26: 55.57 | T26: 55.69 | U26: 55.77 | V26: 55.84 | W26: 55.9 | X26: 55.94 | Y26: 55.97
A27: =DATE(2017, 2, 3) -> 42769 | B27: 56.81 | C27: 57.15 | D27: 57.44 | E27: 57.62 | F27: 57.71 | G27: 57.73 | H27: 57.71 | I27: 57.67 | J27: 57.64 | K27: 57.59 | L27: 57.52 | M27: 57.45 | N27: 53.83 | O27: 54.47 | P27: 54.99 | Q27: 55.41 | R27: 55.72 | S27: 55.91 | T27: 56.04 | U27: 56.13 | V27: 56.21 | W27: 56.27 | X27: 56.31 | Y27: 56.34
A28: =DATE(2017, 2, 6) -> 42772 | B28: 55.72 | C28: 56.1 | D28: 56.44 | E28: 56.68 | F28: 56.81 | G28: 56.86 | H28: 56.85 | I28: 56.83 | J28: 56.81 | K28: 56.77 | L28: 56.71 | M28: 56.65 | N28: 53.01 | O28: 53.63 | P28: 54.16 | Q28: 54.6 | R28: 54.93 | S28: 55.14 | T28: 55.28 | U28: 55.38 | V28: 55.47 | W28: 55.55 | X28: 55.6 | Y28: 55.65
A29: =DATE(2017, 2, 7) -> 42773 | B29: 55.05 | C29: 55.33 | D29: 55.62 | E29: 55.84 | F29: 55.98 | G29: 56.04 | H29: 56.05 | I29: 56.05 | J29: 56.04 | K29: 56.02 | L29: 55.98 | M29: 55.94 | N29: 52.17 | O29: 52.78 | P29: 53.3 | Q29: 53.72 | R29: 54.04 | S29: 54.24 | T29: 54.38 | U29: 54.48 | V29: 54.58 | W29: 54.66 | X29: 54.72 | Y29: 54.77
A30: =DATE(2017, 2, 8) -> 42774 | B30: 55.12 | C30: 55.47 | D30: 55.79 | E30: 56.04 | F30: 56.19 | G30: 56.25 | H30: 56.26 | I30: 56.25 | J30: 56.24 | K30: 56.22 | L30: 56.19 | M30: 56.16 | N30: 52.34 | O30: 52.91 | P30: 53.37 | Q30: 53.76 | R30: 54.07 | S30: 54.27 | T30: 54.42 | U30: 54.54 | V30: 54.64 | W30: 54.72 | X30: 54.77 | Y30: 54.81
A31: =DATE(2017, 2, 9) -> 42775 | B31: 55.63 | C31: 56 | D31: 56.33 | E31: 56.57 | F31: 56.72 | G31: 56.78 | H31: 56.78 | I31: 56.76 | J31: 56.74 | K31: 56.71 | L31: 56.67 | M31: 56.64 | N31: 53 | O31: 53.46 | P31: 53.88 | Q31: 54.25 | R31: 54.55 | S31: 54.76 | T31: 54.91 | U31: 55.03 | V31: 55.13 | W31: 55.21 | X31: 55.26 | Y31: 55.3
A32: =DATE(2017, 2, 10) -> 42776 | B32: 56.7 | C32: 57.06 | D32: 57.36 | E32: 57.55 | F32: 57.66 | G32: 57.7 | H32: 57.67 | I32: 57.61 | J32: 57.56 | K32: 57.5 | L32: 57.44 | M32: 57.38 | N32: 53.86 | O32: 54.33 | P32: 54.78 | Q32: 55.18 | R32: 55.49 | S32: 55.69 | T32: 55.82 | U32: 55.91 | V32: 55.98 | W32: 56.02 | X32: 56.04 | Y32: 56.05
A33: =DATE(2017, 2, 13) -> 42779 | B33: 55.59 | C33: 55.96 | D33: 56.25 | E33: 56.44 | F33: 56.56 | G33: 56.6 | H33: 56.58 | I33: 56.54 | J33: 56.49 | K33: 56.44 | L33: 56.39 | M33: 56.33 | N33: 52.93 | O33: 53.43 | P33: 53.86 | Q33: 54.25 | R33: 54.56 | S33: 54.76 | T33: 54.9 | U33: 55.01 | V33: 55.1 | W33: 55.17 | X33: 55.2 | Y33: 55.22
A34: =DATE(2017, 2, 14) -> 42780 | B34: 55.97 | C34: 56.29 | D34: 56.55 | E34: 56.72 | F34: 56.83 | G34: 56.86 | H34: 56.83 | I34: 56.77 | J34: 56.71 | K34: 56.65 | L34: 56.6 | M34: 56.54 | N34: 53.2 | O34: 53.71 | P34: 54.12 | Q34: 54.48 | R34: 54.78 | S34: 54.98 | T34: 55.12 | U34: 55.22 | V34: 55.29 | W34: 55.35 | X34: 55.37 | Y34: 55.38
A35: =DATE(2017, 2, 15) -> 42781 | B35: 55.75 | C35: 56.1 | D35: 56.35 | E35: 56.51 | F35: 56.62 | G35: 56.65 | H35: 56.62 | I35: 56.56 | J35: 56.5 | K35: 56.44 | L35: 56.39 | M35: 56.33 | N35: 53.11 | O35: 53.6 | P35: 53.99 | Q35: 54.31 | R35: 54.57 | S35: 54.75 | T35: 54.87 | U35: 54.95 | V35: 55.01 | W35: 55.06 | X35: 55.07 | Y35: 55.07
A36: =DATE(2017, 2, 16) -> 42782 | B36: 55.65 | C36: 56 | D36: 56.25 | E36: 56.42 | F36: 56.54 | G36: 56.58 | H36: 56.56 | I36: 56.51 | J36: 56.46 | K36: 56.41 | L36: 56.36 | M36: 56.31 | N36: 53.36 | O36: 53.75 | P36: 54.07 | Q36: 54.33 | R36: 54.52 | S36: 54.64 | T36: 54.72 | U36: 54.77 | V36: 54.81 | W36: 54.84 | X36: 54.85 | Y36: 54.85
A37: =DATE(2017, 2, 17) -> 42783 | B37: 55.81 | C37: 56.11 | D37: 56.33 | E37: 56.49 | F37: 56.6 | G37: 56.64 | H37: 56.62 | I37: 56.56 | J37: 56.5 | K37: 56.44 | L37: 56.39 | M37: 56.33 | N37: 53.4 | O37: 53.78 | P37: 54.12 | Q37: 54.37 | R37: 54.56 | S37: 54.68 | T37: 54.75 | U37: 54.79 | V37: 54.82 | W37: 54.84 | X37: 54.83 | Y37: 54.82
A38: =DATE(2017, 2, 20) -> 42786 | B38: 56.18 | C38: 56.35 | D38: 56.53 | E38: 56.67 | F38: 56.76 | G38: 56.78 | H38: 56.74 | I38: 56.66 | J38: 56.59 | K38: 56.53 | L38: 56.47 | M38: 56.41 | N38: 53.4 | O38: 53.78 | P38: 54.12 | Q38: 54.37 | R38: 54.56 | S38: 54.68 | T38: 54.75 | U38: 54.79 | V38: 54.82 | W38: 54.84 | X38: 54.83 | Y38: 54.82
A39: =DATE(2017, 2, 21) -> 42787 | B39: 56.66 | C39: 56.76 | D39: 56.82 | E39: 56.86 | F39: 56.89 | G39: 56.88 | H39: 56.82 | I39: 56.71 | J39: 56.61 | K39: 56.52 | L39: 56.43 | M39: 56.34 | N39: 54.06 | O39: 54.33 | P39: 54.61 | Q39: 54.81 | R39: 54.96 | S39: 55.04 | T39: 55.07 | U39: 55.06 | V39: 55.04 | W39: 55.01 | X39: 54.96 | Y39: 54.91
A40: =DATE(2017, 2, 22) -> 42788 | B40: 55.84 | C40: 56.04 | D40: 56.18 | E40: 56.28 | F40: 56.35 | G40: 56.36 | H40: 56.31 | I40: 56.2 | J40: 56.09 | K40: 56 | L40: 55.91 | M40: 55.82 | N40: 53.59 | O40: 53.93 | P40: 54.17 | Q40: 54.37 | R40: 54.49 | S40: 54.54 | T40: 54.56 | U40: 54.56 | V40: 54.55 | W40: 54.51 | X40: 54.45 | Y40: 54.39
A41: =DATE(2017, 2, 23) -> 42789 | B41: 56.58 | C41: 56.82 | D41: 56.98 | E41: 57.07 | F41: 57.13 | G41: 57.13 | H41: 57.06 | I41: 56.94 | J41: 56.82 | K41: 56.71 | L41: 56.62 | M41: 56.51 | N41: 54.45 | O41: 54.76 | P41: 54.96 | Q41: 55.13 | R41: 55.23 | S41: 55.27 | T41: 55.27 | U41: 55.25 | V41: 55.22 | W41: 55.16 | X41: 55.09 | Y41: 55.01
...
